/*Short
public class ExceptionTest
{
    static double SafeDivision(double x, double y)
    {
        if (y == 0)
            throw new DivideByZeroException();
        return x / y;
    }

    public static void Main()
    {
        // Input for test purposes. Change the values to see
        // exception handling behavior.
        double a = 98, b = 0;
        double result;

        try
        {
            result = SafeDivision(a, b);
            Console.WriteLine("{0} divided by {1} = {2}", a, b, result);
        }
        catch (DivideByZeroException)
        {
            Console.WriteLine("Attempted divide by zero.");
        }
    }
}*/
/*使用异常
try
{
    TestThrow();
}
catch (CustomException ex)
{
    System.Console.WriteLine(ex.ToString());
}
static void TestThrow()
{
    throw new CustomException("Custom exception in TestThrow()");
}
class CustomException : Exception
{
    public CustomException(string message)
    {
    }
}*/
/*使用异常2
using System;
using System.IO;

namespace Exceptions
{
    public class CatchOrder
    {
        public static void Main()
        {
            try
            {
                using (var sw = new StreamWriter("./test.txt"))
                {
                    sw.WriteLine("Hello");
                }
            }
            // Put the more specific exceptions first.
            catch (DirectoryNotFoundException ex)
            {
                Console.WriteLine(ex);
            }
            catch (FileNotFoundException ex)
            {
                Console.WriteLine(ex);
            }
            // Put the least specific exception last.
            catch (IOException ex)
            {
                Console.WriteLine(ex);
            }
            Console.WriteLine("Done");
        }
    }
}
*/
/*TestFinally*/
